<robot xmlns:xacro="http://www.ros.org/wiki/xacro" name="Staubli" >
  <xacro:property name="ModelPathHead" value="file:///home/zy_jp/planning_test/src/robotic_arm_description/meshes/" />
  <!--Base link  -->
  <link name="base_link">
    <collision>
      <origin xyz="0 0 0" rpy="0 0 0" />
      <geometry>
        <mesh filename="${ModelPathHead}base_link.STL" />
      </geometry>
    </collision>

    <visual>
      <origin xyz="0 0 0" rpy="0 0 0" />
      <geometry>
        <mesh filename="${ModelPathHead}base_link.STL" />
      </geometry>
    </visual>

    <inertial>
      <origin xyz="0 0 0.03" rpy="0 0 0" />
      <mass value="0.54333" />
      <inertia ixx="0.0011488" ixy="-1.8705E-07" ixz="1.2299E-12"
               iyy="0.00069977" iyz="1.123E-13" izz="0.0018411" />
    </inertial>
  </link>
   <gazebo reference="base_link">
    <material>Gazebo/Red</material>
  </gazebo>
  <!-- Link_1 -->
<link name  ="Link1">
    <collision>
      <origin xyz="0 0 0" rpy="0 0 0" />
      <geometry>
        <mesh filename="${ModelPathHead}Link1.STL" />
      </geometry>
    </collision>

    <visual>
      <origin xyz="0 0 0" rpy="0 0 0" />
      <geometry>
        <mesh
          filename="${ModelPathHead}Link1.STL" />
      </geometry>
      <material name="Red">
        <color rgba="1 0 0 1" />
      </material>
    </visual>

    <inertial>
      <origin xyz="-0.042776 0.041899 0.019137" rpy="0 0 0" />
      <mass
        value="1.0968" />
      <inertia ixx="0.0037792" ixy="0.0020035" ixz="3.2611E-06"
               iyy="0.0038578" iyz="-3.2463E-06" izz="0.0074719" />
    </inertial>
  </link>


  <!--  Link_2 -->
  <link name="Link2">
    <collision>
      <origin xyz="0 0 0" rpy="0 0 0" />
      <geometry>
        <mesh
          filename="${ModelPathHead}Link2.STL" />
      </geometry>
      <material name="Red">
        <color rgba="1 0 0 1" />
      </material>
    </collision>

    <inertial>
      <origin xyz="-0.0293915910429697 0.0486285643763861 0.0612274613954139" rpy="0 0 0" />
      <mass value="1.25214738320438" />
      <inertia ixx="0.00418046489133235" ixy="0.000966257495575629" ixz="-5.06683955952671E-06"
               iyy="0.00187013984439792" iyz="1.63783891707448E-05" izz="0.00334362090909904" />
    </inertial>

    <visual>
      <origin xyz="0 0 0" rpy="0 0 0" />
      <geometry>
        <mesh filename="${ModelPathHead}Link2.STL" />
      </geometry>
    </visual>
  </link>

  <!-- Link_3 -->
  <link name="Link3">
    <inertial>
      <origin xyz="0.0735996047362997 -0.180766902087912 0.0291903632102638" rpy="0 0 0" />
      <mass value="0.806622966094275" />
      <inertia ixx="0.00428616079799915" ixy="0.00162064430277941" ixz="1.5763835318075E-07"
               iyy="0.00108394932833737" iyz="1.37328549974522E-07" izz="0.00525748398490944" />
    </inertial>

    <visual>
      <origin xyz="0 0 0" rpy="0 0 0" />
      <geometry>
        <mesh filename="${ModelPathHead}Link3.STL" />
      </geometry>
      <material name="Red">
        <color rgba="1 0 0 1" />
      </material>
    </visual>

    <collision>
      <origin xyz="0 0 0" rpy="0 0 0" />
      <geometry>
        <mesh filename="${ModelPathHead}Link3.STL" />
      </geometry>
    </collision>
  </link>

  <!-- Link_4 -->
  <link name="Link4">
    <inertial>
      <origin xyz="0.0334065400236465 0.056438303721173 -0.0209545212188433" rpy="0 0 0" />
      <mass value="1.08685226595306" />
      <inertia ixx="0.00178938161682911" ixy="-0.000450625341988752" ixz="4.31239421334185E-07"
               iyy="0.00126892274611038" iyz="-1.20971607458933E-06" izz="0.00280043918230883" />
    </inertial>
    <visual>
      <origin xyz="0 0 0" rpy="0 0 0" />
      <geometry>
        <mesh filename="${ModelPathHead}Link4.STL" />
      </geometry>
      <material name="Red">
                <color rgba="1 0 0 1" />
      </material>
    </visual>

    <collision>
      <origin xyz="0 0 0" rpy="0 0 0" />
      <geometry>
        <mesh filename="${ModelPathHead}Link4.STL" />
      </geometry>
    </collision>
  </link>

  <!-- Link_5 -->
  <link name="Link5">
    <inertial>
      <origin xyz="5.06310552090827E-05 -2.5981042822365E-05 -0.0685403600123032" rpy="0 0 0" />
      <mass value="0.691799197761243" />
      <inertia ixx="0.000216370509151489" ixy="1.06668320132473E-05" ixz="3.72994541964734E-07"
               iyy="0.00020139280915018" iyz="-3.05327492712099E-07" izz="0.000275299437122556" />
    </inertial>
    
    <visual>
      <origin  xyz="0 0 0" rpy="0 0 0" />
      <geometry>
        <mesh filename="${ModelPathHead}Link5.STL" />
      </geometry>
      <material name="Red">
        <color rgba="1 0 0 1" />
      </material>
    </visual>

    <collision>
      <origin xyz="0 0 0" rpy="0 0 0" />
      <geometry>
        <mesh filename="${ModelPathHead}Link5.STL" />
      </geometry>
    </collision>
  </link>

  <!-- Link_6 -->
  <link name="Link6">
    <inertial>
      <origin xyz="-0.0445495814666962 0.00855523493492594 -0.00114742473678081" rpy="0 0 0" />
      <mass value="0.0795410960783994" />
      <inertia ixx="1.76237330108251E-05" ixy="1.34537730348688E-11" ixz="1.14220181233844E-10"
               iyy="2.12371160256906E-05" iyz="-3.7993364540014E-07" izz="1.88526908809782E-05" />
    </inertial>

    <visual>
      <origin xyz="0 0 0" rpy="0 0 0" />
      <geometry>
        <mesh filename="${ModelPathHead}Link6.STL" />
      </geometry>
      <material name="Red">
        <color rgba="1 0 0 1" />
      </material>
    </visual>

    <collision>
      <origin xyz="0 0 0" rpy="0 0 0" />
      <geometry>
        <mesh filename="${ModelPathHead}Link6.STL" />
      </geometry>
    </collision>
  </link>


  <!-- Link_7 -->
  <link name="Link7">
    <inertial>
      <origin xyz="-7.7264E-09 3.8005E-10 -0.048391" rpy="0 0 0" />
      <mass value="0.1253" />
      <inertia ixx="3.5728E-05" ixy="-1.2932E-13" ixz="5.2766E-12"
               iyy="3.5728E-05" iyz="-1.6627E-13" izz="5.2631E-05" />
    </inertial>
    <visual>
      <origin xyz="0 0 0" rpy="0 0 0" />
      <geometry>
        <mesh filename="${ModelPathHead}Link7.STL" />
      </geometry>
      <material name="Red">
        <color rgba="1 0 0 1" />
      </material>
    </visual>

    <collision>
      <origin xyz="0 0 0" rpy="0 0 0" />
      <geometry>
        <mesh filename="${ModelPathHead}Link7.STL" />
      </geometry>
    </collision>
  </link>

  <link name="world"/>

  <joint name="base_joint" type="fixed">
        <parent link="world" />
        <child link="base_link" />
        <origin xyz="0 0 0" rpy="0 0 0" />
        <axis xyz="0 0 1" />
  </joint>

  <!-- Joint_1 -->
  <joint name="joint1" type="fixed">
    <parent link="base_link" />
    <child link="Link1" />
    <origin xyz="0.0 0.0 0.0" rpy="0 0 0.77982" />
    <axis xyz="0 0 1" />
  </joint>

  
  <!-- Joint_2 -->
  <joint name="joint2" type="revolute">
    <origin xyz="-0.15712 0.15399 0.032" rpy="0 0 -2.6997" />
    <parent link="Link1" />
    <child link="Link2" />
    <axis xyz="0 0 1" /> 
    <limit lower="-3.14159" upper="3.14159" effort="0" velocity="0" />
  </joint>

  <!-- Joint_3 -->
  <joint name="joint3" type="revolute">
    <parent link="Link2" />
    <child link="Link3" />
    <origin xyz="-0.027759 -0.026066 0.063" rpy="-1.5708 0.88139 1.9199" />
    <axis xyz="0 0 1" /> 
    <limit ower="-3.14159" upper="3.14159" effort="0" velocity="0" />
  </joint>

  <!-- Joint4 -->
  <joint name="joint4" type="revolute">
    <parent link="Link3" />
    <child link="Link4" />
    <origin xyz="0.14542 -0.35107 0.0145" rpy="0 0 1.2681" />
    <axis xyz="0 0 1" />
    <limit lower="-3.14159" upper="3.14159" effort="0" velocity="0" />
  </joint>

  <!-- Joint_5 -->
  <joint name="joint5" type="revolute">
    <parent link="Link4" />
    <child link="Link5" />
    <origin xyz="0.20278 0.37356 -0.0227" rpy="1.5708 -0.5236 2.6443" />
    <axis xyz="0 0 -1" /> 
    <limit lower="-3.14159" upper="3.14159" effort="0" velocity="0" />
  </joint>

  <!-- Joint_6 -->
  <joint name="joint6" type="revolute">
    <origin xyz="-0.021451 0.038875 0.016952" rpy="-1.4264 0 2.075" />
    <parent link="Link5" />
    <child link="Link6" />
    <axis xyz="1 0 0" /> 
    <limit lower="-3.14159" upper="3.14159" effort="0" velocity="0" />
  </joint>

  <!-- Joint_7 -->
  <joint name="joint7" type="revolute">
    <origin xyz="-0.0445 0.028078 -0.0037885" rpy="-1.8373 1.0382 -0.23098" />
    <parent link="Link6" />
    <child link="Link7" />
    <axis xyz="0 0 1" />
    <limit lower="-3.14159" upper="3.14159" effort="0" velocity="0" />
  </joint>

  <gazebo reference="base_link">
        <material>Gazebo/Purple</material>
        <self_collide>false</self_collide>
        <gravity>false</gravity>
  </gazebo>

  <gazebo reference="Link1">
        <material>Gazebo/Purple</material>
        <self_collide>false</self_collide>
        <gravity>false</gravity>
  </gazebo>

  <gazebo reference="Link2">
        <material>Gazebo/Purple</material>
        <self_collide>false</self_collide>
        <gravity>false</gravity>
  </gazebo>

  <gazebo reference="Link3">
        <material>Gazebo/Purple</material>
        <self_collide>false</self_collide>
        <gravity>false</gravity>
  </gazebo>

  <gazebo reference="Link4">
        <material>Gazebo/Purple</material>
        <self_collide>false</self_collide>
        <gravity>false</gravity>
  </gazebo>

  <gazebo reference="Link5">
        <material>Gazebo/Purple</material>
        <self_collide>false</self_collide>
        <gravity>false</gravity>
  </gazebo>

  <gazebo reference="Link6">
        <material>Gazebo/Purple</material>
        <self_collide>false</self_collide>
        <gravity>false</gravity>
  </gazebo>

  <gazebo reference="Link7">
        <material>Gazebo/Purple</material>
        <self_collide>false</self_collide>
        <gravity>false</gravity>
  </gazebo>
</robot>